<?xml version="1.0" ?>
<!-- =================================================================================== -->
<!-- |    This document was autogenerated by xacro from drawer_one_sided_handle.xacro  | -->
<!-- |    EDITING THIS FILE BY HAND IS NOT RECOMMENDED                                 | -->
<!-- =================================================================================== -->
<robot name="double_drawer" xmlns:xacro="http://ros.org/wiki/xacro">
  <material name="omni/Blue">
    <color rgba="0 0 0.8 1"/>
  </material>
  <material name="omni/Red">
    <color rgba="1 0 0 1"/>
  </material>
  <material name="omni/White">
    <color rgba="1 1 1 1"/>
  </material>
  <material name="omni/Green">
    <color rgba="0 1 0 1"/>
  </material>
  <material name="omni/Yellow">
    <color rgba="1 1 0 1"/>
  </material>
  <material name="omni/LightGrey">
    <color rgba="0.6 0.6 0.6 1"/>
  </material>
  <material name="omni/DarkGrey">
    <color rgba="0.4 0.4 0.4 1"/>
  </material>

  <!-- World link -->
  <link name="world">
    <!--<inertial>-->
      <!--<origin rpy="0 0 0" xyz="0 0 0"/>-->
      <!--<mass value=".1"/>-->
      <!--<inertia ixx="1" ixy="0" ixz="0" iyy="1" iyz="0" izz="1"/>-->
    <!--</inertial>-->
  </link>

  <!-- Base link -->
  <link name="base_link">
    <inertial>
      <origin rpy="0 0 0" xyz="0 0 0"/>
      <mass value="1"/> 
      <inertia ixx="0.6667" ixy="0" ixz="0" iyy="0.6667" iyz="0" izz="0.6667"/> <!-- 惯性缩小为 2/3 -->
    </inertial>
  </link>

  <!-- Joint connecting world to base -->
  <joint name="world_to_base" type="fixed">
    <origin rpy="0 0 0" xyz="0 0 0.1"/> 
    <parent link="world"/>
    <child link="base_link"/>
  </joint>

  <!-- Drawer Cabinet (外壳轮廓) -->
  <link name="cabinet">
    <inertial>
      <origin rpy="0 0 0" xyz="0 0 0"/>
      <mass value="1"/> 
      <inertia ixx="0.6667" ixy="0" ixz="0" iyy="0.6667" iyz="0" izz="0.6667"/> <!-- 惯性缩小为 2/3 -->
    </inertial>
  </link>

  <!-- Joint connecting base to cabinet -->
  <joint name="base_to_cabinet" type="fixed">
    <origin rpy="0 0 0" xyz="0 0 0"/> 
    <parent link="base_link"/>
    <child link="cabinet"/>
  </joint>

  <!-- Cabinet Top -->
  <link name="cabinet_top">
    <visual>
      <origin rpy="0 0 0" xyz="0 0 0"/>
      <geometry>
        <box size="0.4133 0.4067 0.0133"/> 
      </geometry>
      <material name="omni/White"/>
    </visual>
    <collision>
      <origin rpy="0 0 0" xyz="0 0 0"/>
      <geometry>
        <box size="0.4133 0.4067 0.0133"/> 
      </geometry>
    </collision>
    <inertial>
      <origin rpy="0 0 0" xyz="0 0 0"/>
      <mass value="1"/> 
      <inertia ixx="0.0067" ixy="0" ixz="0" iyy="0.0067" iyz="0" izz="0.0067"/> <!-- 惯性缩小为 2/3 -->
    </inertial>
  </link>
  <joint name="cabinet_to_top" type="fixed">
    <origin rpy="0 0 0" xyz="0 -0.0033 0.2933"/> 
    <parent link="cabinet"/>
    <child link="cabinet_top"/>
  </joint>

  <!-- Cabinet Bottom -->
  <link name="cabinet_bottom">
    <visual>
      <origin rpy="0 0 0" xyz="0 0 0"/>
      <geometry>
        <box size="0.4133 0.4067 0.0133"/> 
      </geometry>
      <material name="omni/White"/>
    </visual>
    <collision>
      <origin rpy="0 0 0" xyz="0 0 0"/>
      <geometry>
        <box size="0.4133 0.4067 0.0133"/> 
      </geometry>
    </collision>
    <inertial>
      <origin rpy="0 0 0" xyz="0 0 0"/>
      <mass value="1"/> 
      <inertia ixx="0.0067" ixy="0" ixz="0" iyy="0.0067" iyz="0" izz="0.0067"/> <!-- 惯性缩小为 2/3 -->
    </inertial>
  </link>
  <joint name="cabinet_to_bottom" type="fixed">
    <origin rpy="0 0 0" xyz="0 -0.0033 -0.0933"/> 
    <parent link="cabinet"/>
    <child link="cabinet_bottom"/>
  </joint>

  <!-- Cabinet Left Side -->
  <link name="cabinet_left">
    <visual>
      <origin rpy="0 0 0" xyz="0 0 0"/>
      <geometry>
        <box size="0.0067 0.4067 0.3733"/> 
      </geometry>
      <material name="omni/White"/>
    </visual>
    <collision>
      <origin rpy="0 0 0" xyz="0 0 0"/>
      <geometry>
        <box size="0.0067 0.4067 0.3733"/> 
      </geometry>
    </collision>
    <inertial>
      <origin rpy="0 0 0" xyz="0 0 0"/>
      <mass value="1"/> 
      <inertia ixx="0.0067" ixy="0" ixz="0" iyy="0.0067" iyz="0" izz="0.0067"/> <!-- 惯性缩小为 2/3 -->
    </inertial>
  </link>
  <joint name="cabinet_to_left" type="fixed">
    <origin rpy="0 0 0" xyz="-0.2033 -0.0033 0.1"/> 
    <parent link="cabinet"/>
    <child link="cabinet_left"/>
  </joint>

  <!-- Cabinet Right Side -->
  <link name="cabinet_right">
    <visual>
      <origin rpy="0 0 0" xyz="0 0 0"/>
      <geometry>
        <box size="0.0067 0.4067 0.3733"/> 
      </geometry>
      <material name="omni/White"/>
    </visual>
    <collision>
      <origin rpy="0 0 0" xyz="0 0 0"/>
      <geometry>
        <box size="0.0067 0.4067 0.3733"/> 
      </geometry>
    </collision>
    <inertial>
      <origin rpy="0 0 0" xyz="0 0 0"/>
      <mass value="1"/> 
      <inertia ixx="0.0067" ixy="0" ixz="0" iyy="0.0067" iyz="0" izz="0.0067"/> <!-- 惯性缩小为 2/3 -->
    </inertial>
  </link>
  <joint name="cabinet_to_right" type="fixed">
    <origin rpy="0 0 0" xyz="0.2033 -0.0033 0.1"/> 
    <parent link="cabinet"/>
    <child link="cabinet_right"/>
  </joint>

  <!-- Cabinet Back -->
  <link name="cabinet_back">
    <visual>
      <origin rpy="0 0 0" xyz="0 0 0"/>
      <geometry>
        <box size="0.4 0.0067 0.3733"/> 
      </geometry>
      <material name="omni/White"/>
    </visual>
    <collision>
      <origin rpy="0 0 0" xyz="0 0 0"/>
      <geometry>
        <box size="0.4 0.0067 0.3733"/> 
      </geometry>
    </collision>
    <inertial>
      <origin rpy="0 0 0" xyz="0 0 0"/>
      <mass value="1"/> 
      <inertia ixx="0.0067" ixy="0" ixz="0" iyy="0.0067" iyz="0" izz="0.0067"/> <!-- 惯性缩小为 2/3 -->
    </inertial>
  </link>
  <joint name="cabinet_to_back" type="fixed">
    <origin rpy="0 0 0" xyz="0 -0.2033 0.1"/> 
    <parent link="cabinet"/>
    <child link="cabinet_back"/>
  </joint>

  <!-- Cabinet Center -->
  <link name="cabinet_center">
    <visual>
      <origin rpy="0 0 0" xyz="0 0 0"/>
      <geometry>
        <box size="0.4 0.4 0.0267"/> 
      </geometry>
      <material name="omni/White"/>
    </visual>
    <collision>
      <origin rpy="0 0 0" xyz="0 0 0"/>
      <geometry>
        <box size="0.4 0.4 0.0333"/> 
      </geometry>
    </collision>
    <inertial>
      <origin rpy="0 0 0" xyz="0 0 0"/>
      <mass value="1"/> 
      <inertia ixx="0.0067" ixy="0" ixz="0" iyy="0.0067" iyz="0" izz="0.0067"/> <!-- 惯性缩小为 2/3 -->
    </inertial>
  </link>
  <joint name="cabinet_to_center" type="fixed">
    <origin rpy="0 0 0" xyz="0 0 0.1"/> 
    <parent link="cabinet"/>
    <child link="cabinet_center"/>
  </joint>

  <!-- First Drawer -->
  <link name="drawer_1">
    <inertial>
      <origin rpy="0 0 0" xyz="0 0 0"/>
      <mass value="1"/> 
      <inertia ixx="0.6667" ixy="0" ixz="0" iyy="0.6667" iyz="0" izz="0.6667"/> <!-- 惯性缩小为 2/3 -->
    </inertial>
  </link>

  <!-- Joint connecting base to first drawer -->
  <joint name="base_drawer_1_joint" type="prismatic">
    <origin rpy="0 0 0" xyz="0 0 0"/> 
    <parent link="base_link"/>
    <child link="drawer_1"/>
    <dynamics damping="0.0" friction="0.01"/>
    <limit effort="10" lower="0.0" upper="100" velocity="100.0"/>
    <axis xyz="0 1 0"/>
  </joint>

  <!-- First Drawer Walls -->
  <link name="drawer_1_left_wall">
    <visual>
      <origin rpy="0 0 0" xyz="0 0 0"/>
      <geometry>
        <box size="0.4 0.0133 0.15"/> 
      </geometry>
      <material name="omni/LightGrey"/>
    </visual>
    <collision>
      <origin rpy="0 0 0" xyz="0 0 0.0"/>
      <geometry>
        <box size="0.4 0.0133 0.15"/> 
      </geometry>
    </collision>
    <inertial>
      <origin rpy="0 0 0" xyz="0 0 0"/>
      <mass value="1"/> 
      <inertia ixx="0.0017" ixy="0" ixz="0" iyy="0.0187" iyz="0" izz="0.0170"/> <!-- 惯性缩小为 2/3 -->
    </inertial>
  </link>
  <joint name="drawer_1_2_dlw" type="fixed">
    <origin rpy="0 0 0" xyz="0 -0.1933 0"/> 
    <parent link="drawer_1"/>
    <child link="drawer_1_left_wall"/>
  </joint>

  <link name="drawer_1_right_wall">
    <visual>
      <origin rpy="0 0 0" xyz="0 0 0"/>
      <geometry>
        <box size="0.4 0.0133 0.15"/> 
      </geometry>
      <material name="omni/LightGrey"/>
    </visual>
    <collision>
      <origin rpy="0 0 0" xyz="0 0 0.0"/>
      <geometry>
        <box size="0.4 0.0133 0.15"/> 
      </geometry>
    </collision>
    <inertial>
      <origin rpy="0 0 0" xyz="0 0 0"/>
      <mass value="1"/> 
      <inertia ixx="0.0017" ixy="0" ixz="0" iyy="0.0187" iyz="0" izz="0.0170"/> <!-- 惯性缩小为 2/3 -->
    </inertial>
  </link>
  <joint name="drawer_1_2_drw" type="fixed">
    <origin rpy="0 0 0" xyz="0 0.1933 0"/> 
    <parent link="drawer_1"/>
    <child link="drawer_1_right_wall"/>
  </joint>

  <link name="drawer_1_bottom_wall">
    <contact>
      <friction_anchor/>
      <lateral_friction value="1.0"/>
    </contact>
    <visual>
      <origin rpy="0 0 0" xyz="0 0 0"/>
      <geometry>
        <box size="0.4 0.4 0.0133"/> 
      </geometry>
      <material name="omni/LightGrey"/>
    </visual>
    <collision>
      <origin rpy="0 0 0" xyz="0 0 0.0"/>
      <geometry>
        <box size="0.4 0.4 0.0133"/> 
      </geometry>
    </collision>
    <inertial>
      <origin rpy="0 0 0" xyz="0 0 0"/>
      <mass value="1"/> 
      <inertia ixx="0.0073" ixy="0" ixz="0" iyy="0.0170" iyz="0" izz="0.0243"/> <!-- 惯性缩小为 2/3 -->
    </inertial>
  </link>
  <joint name="drawer_1_2_dbow" type="fixed">
    <origin rpy="0 0 0" xyz="0 0 -0.08"/> 
    <parent link="drawer_1"/>
    <child link="drawer_1_bottom_wall"/>
  </joint>

  <link name="drawer_1_back_wall">
    <visual>
      <origin rpy="0 0 0" xyz="0 0 0"/>
      <geometry>
        <box size="0.0133 0.4 0.15"/> 
      </geometry>
      <material name="omni/LightGrey"/>
    </visual>
    <collision>
      <origin rpy="0 0 0" xyz="0 0 0.0"/>
      <geometry>
        <box size="0.0133 0.4 0.15"/> 
      </geometry>
    </collision>
    <inertial>
      <origin rpy="0 0 0" xyz="0 0 0"/>
      <mass value="1"/> 
      <inertia ixx="0.0094" ixy="0" ixz="0" iyy="0.0022" iyz="0" izz="0.0145"/> <!-- 惯性缩小为 2/3 -->
    </inertial>
  </link>
  <joint name="drawer_1_2_dbaw" type="fixed">
    <origin rpy="0 0 0" xyz="0.1933 0 0"/> 
    <parent link="drawer_1"/>
    <child link="drawer_1_back_wall"/>
  </joint>

  <link name="drawer_1_front_wall">
    <visual>
      <origin rpy="0 0 0" xyz="0 0 0"/>
      <geometry>
        <box size="0.0133 0.4 0.15"/> 
      </geometry>
      <material name="omni/LightGrey"/>
    </visual>
    <collision>
      <origin rpy="0 0 0" xyz="0 0 0.0"/>
      <geometry>
        <box size="0.0133 0.4 0.15"/> 
      </geometry>
    </collision>
    <inertial>
      <origin rpy="0 0 0" xyz="0 0 0"/>
      <mass value="1"/> 
      <inertia ixx="0.0094" ixy="0" ixz="0" iyy="0.0022" iyz="0" izz="0.0145"/> <!-- 惯性缩小为 2/3 -->
    </inertial>
  </link>
  <joint name="drawer_1_2_dfw" type="fixed">
    <origin rpy="0 0 0" xyz="-0.1933 0 0"/> 
    <parent link="drawer_1"/>
    <child link="drawer_1_front_wall"/>
  </joint>

  <!-- Second Drawer -->
  <link name="drawer_2">
    <inertial>
      <origin rpy="0 0 0" xyz="0 0 0"/>
      <mass value="1"/> 
      <inertia ixx="0.6667" ixy="0" ixz="0" iyy="0.6667" iyz="0" izz="0.6667"/> <!-- 惯性缩小为 2/3 -->
    </inertial>
  </link>

  <!-- Joint connecting base to second drawer -->
  <joint name="base_drawer_2_joint" type="prismatic">
    <origin rpy="0 0 0" xyz="0 0 0.2"/> 
    <parent link="base_link"/>
    <child link="drawer_2"/>
    <dynamics damping="0.0" friction="0.01"/>
    <limit effort="10" lower="0.0" upper="100" velocity="100.0"/>
    <axis xyz="0 1 0"/>
  </joint>

  <!-- Second Drawer Walls -->
  <link name="drawer_2_left_wall">
    <visual>
      <origin rpy="0 0 0" xyz="0 0 0"/>
      <geometry>
        <box size="0.4 0.0133 0.15"/> 
      </geometry>
      <material name="omni/LightGrey"/>
    </visual>
    <collision>
      <origin rpy="0 0 0" xyz="0 0 0.0"/>
      <geometry>
        <box size="0.4 0.0133 0.15"/> 
      </geometry>
    </collision>
    <inertial>
      <origin rpy="0 0 0" xyz="0 0 0"/>
      <mass value="1"/> 
      <inertia ixx="0.0017" ixy="0" ixz="0" iyy="0.0187" iyz="0" izz="0.0170"/> <!-- 惯性缩小为 2/3 -->
    </inertial>
  </link>
  <joint name="drawer_2_2_dlw" type="fixed">
    <origin rpy="0 0 0" xyz="0 -0.1933 0"/> 
    <parent link="drawer_2"/>
    <child link="drawer_2_left_wall"/>
  </joint>

  <link name="drawer_2_right_wall">
    <visual>
      <origin rpy="0 0 0" xyz="0 0 0"/>
      <geometry>
        <box size="0.4 0.0133 0.15"/> 
      </geometry>
      <material name="omni/LightGrey"/>
    </visual>
    <collision>
      <origin rpy="0 0 0" xyz="0 0 0.0"/>
      <geometry>
        <box size="0.4 0.0133 0.15"/> 
      </geometry>
    </collision>
    <inertial>
      <origin rpy="0 0 0" xyz="0 0 0"/>
      <mass value="1"/> 
      <inertia ixx="0.0017" ixy="0" ixz="0" iyy="0.0187" iyz="0" izz="0.0170"/> <!-- 惯性缩小为 2/3 -->
    </inertial>
  </link>
  <joint name="drawer_2_2_drw" type="fixed">
    <origin rpy="0 0 0" xyz="0 0.1933 0"/> 
    <parent link="drawer_2"/>
    <child link="drawer_2_right_wall"/>
  </joint>

  <link name="drawer_2_bottom_wall">
    <contact>
      <friction_anchor/>
      <lateral_friction value="5"/>
    </contact>
    <visual>
      <origin rpy="0 0 0" xyz="0 0 0"/>
      <geometry>
        <box size="0.4 0.4 0.0133"/> 
      </geometry>
      <material name="omni/LightGrey"/>
    </visual>
    <collision>
      <origin rpy="0 0 0" xyz="0 0 0.0"/>
      <geometry>
        <box size="0.4 0.4 0.0133"/> 
      </geometry>
    </collision>
    <inertial>
      <origin rpy="0 0 0" xyz="0 0 0"/>
      <mass value="1"/> 
      <inertia ixx="0.0073" ixy="0" ixz="0" iyy="0.0170" iyz="0" izz="0.0243"/> <!-- 惯性缩小为 2/3 -->
    </inertial>
  </link>
  <joint name="drawer_2_2_dbow" type="fixed">
    <origin rpy="0 0 0" xyz="0 0 -0.08"/> 
    <parent link="drawer_2"/>
    <child link="drawer_2_bottom_wall"/>
  </joint>

  <link name="drawer_2_back_wall">
    <visual>
      <origin rpy="0 0 0" xyz="0 0 0"/>
      <geometry>
        <box size="0.0133 0.4 0.15"/> 
      </geometry>
      <material name="omni/LightGrey"/>
    </visual>
    <collision>
      <origin rpy="0 0 0" xyz="0 0 0"/>
      <geometry>
        <box size="0.0133 0.4 0.15"/> 
      </geometry>
    </collision>
    <inertial>
      <origin rpy="0 0 0" xyz="0 0 0"/>
      <mass value="1"/> 
      <inertia ixx="0.0094" ixy="0" ixz="0" iyy="0.0022" iyz="0" izz="0.0145"/> <!-- 惯性缩小为 2/3 -->
    </inertial>
  </link>
  <joint name="drawer_2_2_dbaw" type="fixed">
    <origin rpy="0 0 0" xyz="0.1933 0 0"/> 
    <parent link="drawer_2"/>
    <child link="drawer_2_back_wall"/>
  </joint>

  <link name="drawer_2_front_wall">
    <visual>
      <origin rpy="0 0 0" xyz="0 0 0"/>
      <geometry>
        <box size="0.0133 0.4 0.15"/> 
      </geometry>
      <material name="omni/LightGrey"/>
    </visual>
    <collision>
      <origin rpy="0 0 0" xyz="0 0 0"/>
      <geometry>
        <box size="0.0133 0.4 0.15"/> 
      </geometry>
    </collision>
    <inertial>
      <origin rpy="0 0 0" xyz="0 0 0"/>
      <mass value="1"/> 
      <inertia ixx="0.0094" ixy="0" ixz="0" iyy="0.0022" iyz="0" izz="0.0145"/> <!-- 惯性缩小为 2/3 -->
    </inertial>
  </link>
  <joint name="drawer_2_2_dfw" type="fixed">
    <origin rpy="0 0 0" xyz="-0.1933 0 0"/> 
    <parent link="drawer_2"/>
    <child link="drawer_2_front_wall"/>
  </joint>

  <!-- Handle for First Drawer -->
  <link name="handle_1">
    <contact>
      <friction_anchor/>
      <lateral_friction value="5"/>
    </contact>
    <visual>
      <origin rpy="0 0 0" xyz="0 0 0"/>
      <geometry>
        <box size="0.04 0.05 0.04"/> 
      </geometry>
      <material name="omni/White"/>
    </visual>
    <collision>
      <origin rpy="0 0 0" xyz="0 0 0.0"/>
      <geometry>
        <box size="0.04 0.05 0.04"/> 
      </geometry>
    </collision>
    <inertial>
      <origin rpy="0 0 0" xyz="0 0 0"/>
      <mass value="1"/> 
      <inertia ixx="1.3333e-05" ixy="0" ixz="0" iyy="6.6667e-05" iyz="0" izz="6.6667e-05"/> <!-- 惯性缩小为 2/3 -->
    </inertial>
  </link>
  <joint name="drawer_1_2_handle_1" type="fixed">
    <origin rpy="0 0 0" xyz="0 0.2133 0"/> 
    <parent link="drawer_1"/>
    <child link="handle_1"/>
  </joint>

  <!-- Handle for Second Drawer -->
  <link name="handle_2">
    <contact>
      <friction_anchor/>
      <lateral_friction value="5"/>
    </contact>
    <visual>
      <origin rpy="0 0 0" xyz="0 0 0"/>
      <geometry>
        <box size="0.04 0.05 0.04"/> 
      </geometry>
      <material name="omni/White"/>
    </visual>
    <collision>
      <origin rpy="0 0 0" xyz="0 0 0"/>
      <geometry>
        <box size="0.04 0.05 0.04"/> 
      </geometry>
    </collision>
    <inertial>
      <origin rpy="0 0 0" xyz="0 0 0"/>
      <mass value="1"/> 
      <inertia ixx="1.3333e-05" ixy="0" ixz="0" iyy="6.6667e-05" iyz="0" izz="6.6667e-05"/> <!-- 惯性缩小为 2/3 -->
    </inertial>
  </link>
  <joint name="drawer_2_2_handle_2" type="fixed">
    <origin rpy="0 0 0" xyz="0 0.2133 0"/> 
    <parent link="drawer_2"/>
    <child link="handle_2"/>
  </joint>

  <!-- Drawer Object Position -->
  <link name="drawer_obj_pos">
    <contact>
      <friction_anchor/>
      <lateral_friction value="1.0"/>
    </contact>
    <inertial>
      <origin rpy="0 0 0" xyz="0 0 0"/>
      <mass value="1"/> 
      <inertia ixx="0.0073" ixy="0" ixz="0" iyy="0.0170" iyz="0" izz="0.0243"/> <!-- 惯性缩小为 2/3 -->
    </inertial>
  </link>
  <joint name="dbow2dop" type="fixed">
    <origin rpy="0 0 0" xyz="0.1067 0 0.04"/> 
    <parent link="drawer_1_bottom_wall"/>
    <child link="drawer_obj_pos"/>
  </joint>
</robot>


<!-- https://mymodelrobot.appspot.com/5629499534213120 visulization -->